---
layout:     post
title:      Promise相关
description: Promise相关
date:       2018-11-23
author:     Eric
header-img: img/post-bg-2015.jpg
catalog: true
tags:
    - promise
    - 知识点
    - 前端
---

> promise.then(...).catch(...);与promise.then(..., ...);并不等价，
尤其注意当promise.then(...).catch(...);中的then会抛异常的情况下。


```
promise
    .then(...)    //返回一个新的promise，如果then之前的promise是rejected则延续
    .catch(...);    //又返回一个新的promise，如果catch之前的promise是resolved则延续

promise
    //返回一个新的promise
    //如果then之前的promise是resolved，则由第一个参数返回
    //如果then之前的promise是rejected，则由第二个参数返回。
    .then(..., ...);    
```


###### 例子：

```
const fn = () => {
    throw 2;
}

//promise.then(...).catch(...);
Promise.resolve(1)         //{ [[PromiseStatus]]:"resolved", [[PromiseValue]]:1 }
    .then(v => {           //1
        fn();              //抛异常了，then返回一个rejected的promise
        return 3;          //后面不执行了
    })                     //{ [[PromiseStatus]]:"rejected", [[PromiseValue]]:2 }
    .catch(v => {          //v是throw的值2
        console.log(v);    //2
        return 4;          //catch返回一个resolved且值为4的promise
    });                    //{ [[PromiseStatus]]:"resolved", [[PromiseValue]]:4 }
//程序最后正常结束

//promise.then(..., ...);
Promise.resolve(1)         //{ [[PromiseStatus]]:"resolved", [[PromiseValue]]:1 }
    .then(
        v => {             //1
            fn();          //抛异常了，then返回一个rejected的promise
            return 3;      //后面不执行了
        },
        v => {             //这里只有then之前是rejected才执行
            console.log(v);//不执行
            return 4;      //不执行
        }
    );                     //{ [[PromiseStatus]]:"rejected", [[PromiseValue]]:2 }
//程序最后抛异常：Uncaught (in promise) 2
```
